
2024-07-18 17:12:12.157681 - Imputed missing values in 대장아파트_거리 with median value 10015.45703125
Traceback (most recent call last):
  File "/data/ephemeral/home/code/Team3-DTQ_code.trial.third.py", line 348, in <module>
    test_data = preprocess_data(test_data)
  File "/data/ephemeral/home/code/Team3-DTQ_code.trial.third.py", line 323, in preprocess_data
    df = df[selected_features + ['target']]
  File "/opt/conda/lib/python3.10/site-packages/pandas/core/frame.py", line 3813, in __getitem__
    indexer = self.columns._get_indexer_strict(key, "columns")[1]
  File "/opt/conda/lib/python3.10/site-packages/pandas/core/indexes/base.py", line 6070, in _get_indexer_strict
    self._raise_if_missing(keyarr, indexer, axis_name)
  File "/opt/conda/lib/python3.10/site-packages/pandas/core/indexes/base.py", line 6133, in _raise_if_missing
    raise KeyError(f"{not_found} not in index")
KeyError: "['target'] not in index"
Traceback (most recent call last):
  File "/data/ephemeral/home/code/Team3-DTQ_code.trial.third.py", line 348, in <module>
    test_data = preprocess_data(test_data)
  File "/data/ephemeral/home/code/Team3-DTQ_code.trial.third.py", line 323, in preprocess_data
    df = df[selected_features + ['target']]
  File "/opt/conda/lib/python3.10/site-packages/pandas/core/frame.py", line 3813, in __getitem__
    indexer = self.columns._get_indexer_strict(key, "columns")[1]
  File "/opt/conda/lib/python3.10/site-packages/pandas/core/indexes/base.py", line 6070, in _get_indexer_strict
    self._raise_if_missing(keyarr, indexer, axis_name)
  File "/opt/conda/lib/python3.10/site-packages/pandas/core/indexes/base.py", line 6133, in _raise_if_missing
    raise KeyError(f"{not_found} not in index")
KeyError: "['target'] not in index"