
2024-07-18 17:39:01.388559 - Imputed missing values in 대장아파트_거리 with median value 10015.45703125
2024-07-18 17:39:03.708888 - Imputed missing values in 대장아파트_거리 with median value 10016.3232421875
Traceback (most recent call last):
  File "/opt/conda/lib/python3.10/site-packages/pandas/core/indexes/base.py", line 3802, in get_loc
    return self._engine.get_loc(casted_key)
  File "pandas/_libs/index.pyx", line 138, in pandas._libs.index.IndexEngine.get_loc
  File "pandas/_libs/index.pyx", line 165, in pandas._libs.index.IndexEngine.get_loc
  File "pandas/_libs/hashtable_class_helper.pxi", line 5745, in pandas._libs.hashtable.PyObjectHashTable.get_item
  File "pandas/_libs/hashtable_class_helper.pxi", line 5753, in pandas._libs.hashtable.PyObjectHashTable.get_item
KeyError: '계약일'
The above exception was the direct cause of the following exception:
Traceback (most recent call last):
  File "/data/ephemeral/home/code/Team3-DTQ_code.trial.third.py", line 356, in <module>
    train_data['계약일'] = train_data['계약일'].apply(lambda x: f'{x:02d}')
  File "/opt/conda/lib/python3.10/site-packages/pandas/core/frame.py", line 3807, in __getitem__
    indexer = self.columns.get_loc(key)
  File "/opt/conda/lib/python3.10/site-packages/pandas/core/indexes/base.py", line 3804, in get_loc
    raise KeyError(key) from err
KeyError: '계약일'
Traceback (most recent call last):
  File "/opt/conda/lib/python3.10/site-packages/pandas/core/indexes/base.py", line 3802, in get_loc
    return self._engine.get_loc(casted_key)
  File "pandas/_libs/index.pyx", line 138, in pandas._libs.index.IndexEngine.get_loc
  File "pandas/_libs/index.pyx", line 165, in pandas._libs.index.IndexEngine.get_loc
  File "pandas/_libs/hashtable_class_helper.pxi", line 5745, in pandas._libs.hashtable.PyObjectHashTable.get_item
  File "pandas/_libs/hashtable_class_helper.pxi", line 5753, in pandas._libs.hashtable.PyObjectHashTable.get_item
KeyError: '계약일'
The above exception was the direct cause of the following exception:
Traceback (most recent call last):
  File "/data/ephemeral/home/code/Team3-DTQ_code.trial.third.py", line 356, in <module>
    train_data['계약일'] = train_data['계약일'].apply(lambda x: f'{x:02d}')
  File "/opt/conda/lib/python3.10/site-packages/pandas/core/frame.py", line 3807, in __getitem__
    indexer = self.columns.get_loc(key)
  File "/opt/conda/lib/python3.10/site-packages/pandas/core/indexes/base.py", line 3804, in get_loc
    raise KeyError(key) from err
KeyError: '계약일'